Workbook

Sheet Orders
A1: Order ID | B1: Customer ID | C1: Customer Country | D1: Order Datetime | E1: Order Source | F1: Sales POC | G1: Order Value
A2: 1597 | B2: 856 | C2: USA | D2: 45275.035 | E2: Other | F2: Kwai Yu | G2: 412
A3: 2011 | B3: 525 | C3: India | D3: 45045.986 | E3: Whatsapp | F3: Paul Henriot | G3: 4551
A4: 2822 | B4: 1614 | C4: USA | D4: 45290.015 | E4: Whatsapp | F4: Daniel Da Cunha | G4: 3960
A5: 2889 | B5: 743 | C5: USA | D5: 45258.022 | E5: Whatsapp | F5: Julie Young | G5: 8397
A6: 3971 | B6: 20 | C6: USA | D6: 45225.966 | E6: Website | F6: Julie Brown | G6: 5545
A7: 4111 | B7: 1367 | C7: Italy | D7: 44993.953 | E7: App | F7: Juri Hirano | G7: 7800
A8: 4801 | B8: 945 | C8: France | D8: 44975.016 | E8: Other | F8: Martine Rance | G8: 4674
A9: 5719 | B9: 218 | C9: France | D9: 45253.049 | E9: Website | F9: Veysel Oeztan | G9: 5954
A10: 5846 | B10: 264 | C10: USA | D10: 45283.056 | E10: Website | F10: Julie Murphy | G10: 9887
A11: 7615 | B11: 566 | C11: USA | D11: 45233.99 | E11: Whatsapp | F11: Dominique Perrier | G11: 8303
A12: 8568 | B12: 1414 | C12: USA | D12: 45133.008 | E12: App | F12: Peter Ferguson | G12: 8969
A13: 9339 | B13: 1681 | C13: Spain | D13: 45278.027 | E13: App | F13: Michael Frick | G13: 2782
... A335: 237369 | B335: 401 | C335: India | D335: 45056.016 | E335: App | F335: Palle Ibsen | G335: 2313
A336: 238602 | B336: 153 | C336: USA | D336: 45017.05 | F336: Jonas Bergulfsen | G336: 951
A337: 238793 | B337: 1574 | C337: Austria | D337: 45026.087 | E337: Whatsapp | F337: Marie Bertrand | G337: 3650
A338: 238839 | B338: 766 | C338: USA | D338: 45092.036 | E338: App | F338: Jeff Young | G338: 1367
A339: 241257 | B339: 1374 | C339: France | D339: 45027.065 | E339: Other | F339: Paul Henriot | G339: 6819
A340: 241334 | B340: 864 | C340: USA | D340: 44939.027 | E340: Whatsapp | F340: Akiko Shimamura | G340: 3422
A341: 242256 | B341: 504 | C341: Finland | D341: 45123.077 | E341: Other | F341: Valarie Nelson | G341: 3986
A342: 243319 | B342: 818 | C342: France | D342: 45072.974 | E342: Whatsapp | F342: Valarie Nelson | G342: 2539
A343: 243485 | B343: 633 | C343: France | D343: 45119.011 | E343: Website | F343: Julie King | G343: 6552
A344: 245474 | B344: 40 | C344: Australia | D344: 45248.967 | E344: Other | F344: Arnold Cruz | G344: 3933
A345: 246033 | B345: 1715 | C345: USA | D345: 45265.981 | E345: Other | F345: Laurence Lebihan | G345: 5126
A346: 246834 | B346: 808 | C346: USA | D346: 45134.024 | E346: Other | F346: Valarie Nelson | G346: 9507
A347: 246988 | B347: 243 | C347: USA | D347: 45092.028 | E347: Whatsapp | F347: Allen Nelson | G347: 4264
A348: 247011 | B348: 1809 | C348: USA | D348: 45271.978 | E348: Website | F348: Julie Brown | G348: 4533
... A387: 276276 | B387: 1442 | C387: USA | D387: 45174.062 | E387: Website | F387: Palle Ibsen | G387: 5165
A388: 276403 | B388: 1356 | D388: 45183.999 | E388: Website | F388: Michael Frick | G388: 8633
A389: 276698 | B389: 43 | C389: Singapore | D389: 45057.045 | E389: Other | F389: Marie Bertrand | G389: 9942
A390: 277038 | B390: 1677 | C390: Italy | D390: 45139.939 | E390: Website | F390: Jeff Young | G390: 2455
A391: 279106 | B391: 104 | C391: Australia | D391: 44940.037 | E391: Website | F391: Diego Freyre | G391: 4768
A392: 279515 | B392: 713 | C392: Finland | D392: 45184.958 | E392: App | F392: Valarie Nelson | G392: 4633
A393: 279963 | B393: 1775 | C393: USA | D393: 45226.003 | E393: App | F393: Valarie Nelson | G393: 7812
A394: 280459 | B394: 457 | C394: Denmark | D394: 45195.988 | E394: Whatsapp | F394: Diego Freyre | G394: 3197
A395: 280739 | B395: 138 | C395: USA | D395: 45113.984 | E395: Whatsapp | F395: Janine Labrune | G395: 2453
A396: 281193 | B396: 1522 | C396: USA | D396: 45002.01 | E396: Website | F396: Arnold Cruz | G396: 6173
A397: 281454 | B397: 1413 | C397: Spain | D397: 45186.994 | E397: Other | F397: Laurence Lebihan | G397: 5802
A398: 281813 | B398: 331 | C398: Singapore | D398: 45098.082 | E398: App | F398: Valarie Nelson | G398: 5117
A399: 283066 | B399: 956 | C399: France | D399: 44963.078 | E399: App | F399: Allen Nelson | G399: 5819
...

Sheet Orders D
A1: Order ID | B1: Customer ID | C1: Customer Country | D1: Order Datetime | E1: Order Source | F1: Sales POC | G1: Order Value | H1: Customer Country | I1: Gender | J1: Age | K1: Category | L1: Age_group | M1: Month | N1: Day Of The Week | O1: Time | P1: Hour of the Day | Q1: Customer type | R1: Customer Recency Type | S1: Recency | W1: Website | X1: Whatsapp | Y1: App | Z1: Other | AA1: Blanks
A2: 1265561 | B2: 1 | C2: France | D2: 44985.024 | E2: Website | F2: Kalle Suominen | G2: 3338 | H2: =VLOOKUP(B2,'Customers (2)'!$A$1:$F$2501,2,0) -> France | I2: =VLOOKUP(B2,'Customers (2)'!$A$1:$F$2501,3,0) -> M | J2: =VLOOKUP(B2,'Customers (2)'!$A$1:$F$2501,4,0) -> 31 | K2: =VLOOKUP(B2,'Customers (2)'!$A$1:$F$2501,5,0) -> A | L2: =VLOOKUP(B2,'Customers (2)'!$A$1:$F$2501,6,0) -> Young | M2: =TEXT(D2,"MMMM") -> February | N2: =TEXT(D2,"dddd") -> Tuesday | O2: =TEXT(D2,"HH:mm:ss") -> 00:34:00 | P2: =HOUR(D2) -> 0 | Q2: =VLOOKUP(B2,'Analysis 1.3'!$AA$1:$AF$1454,5,FALSE) -> One time | R2: =VLOOKUP(B2,'Analysis 1.3'!$AA$1:$AF$1454,6,FALSE) -> Lost | S2: =VLOOKUP(B2,'Analysis 1.3'!$AA$1:$AF$1454,4,FALSE) -> 306.95833 | V2: France | W2: =COUNTIFS($C$1:$C$2501,$V2,$E$1:$E$2501,W$1) -> 72 | X2: =COUNTIFS($C$1:$C$2501,$V2,$E$1:$E$2501,X$1) -> 90 | Y2: =COUNTIFS($C$1:$C$2501,$V2,$E$1:$E$2501,Y$1) -> 72 | Z2: =COUNTIFS($C$1:$C$2501,$V2,$E$1:$E$2501,Z$1) -> 88 | AA2: =COUNTIFS($C$1:$C$2501,$V2,$E$1:$E$2501,"") -> 1
A3: 1068397 | B3: 3 | C3: USA | D3: 45028.042 | E3: Other | F3: Julie Brown | G3: 9183 | H3: =VLOOKUP(B3,'Customers (2)'!$A$1:$F$2501,2,0) -> USA | I3: =VLOOKUP(B3,'Customers (2)'!$A$1:$F$2501,3,0) -> M | J3: =VLOOKUP(B3,'Customers (2)'!$A$1:$F$2501,4,0) -> 39 | K3: =VLOOKUP(B3,'Customers (2)'!$A$1:$F$2501,5,0) -> A | L3: =VLOOKUP(B3,'Customers (2)'!$A$1:$F$2501,6,0) -> Middle | M3: =TEXT(D3,"MMMM") -> April | N3: =TEXT(D3,"dddd") -> Wednesday | O3: =TEXT(D3,"HH:mm:ss") -> 01:01:00 | P3: =HOUR(D3) -> 1 | Q3: =VLOOKUP(B3,'Analysis 1.3'!$AA$1:$AF$1454,5,FALSE) -> One time | R3: =VLOOKUP(B3,'Analysis 1.3'!$AA$1:$AF$1454,6,FALSE) -> Lost | S3: =VLOOKUP(B3,'Analysis 1.3'!$AA$1:$AF$1454,4,FALSE) -> 263.93958 | V3: USA | W3: =COUNTIFS($C$1:$C$2501,$V3,$E$1:$E$2501,W$1) -> 223 | X3: =COUNTIFS($C$1:$C$2501,$V3,$E$1:$E$2501,X$1) -> 227 | Y3: =COUNTIFS($C$1:$C$2501,$V3,$E$1:$E$2501,Y$1) -> 233 | Z3: =COUNTIFS($C$1:$C$2501,$V3,$E$1:$E$2501,Z$1) -> 193 | AA3: =COUNTIFS($C$1:$C$2501,$V3,$E$1:$E$2501,"") -> 9 | AC3: Male | AD3: =COUNTIF(I2:I2501, "M") -> 1224
A4: 1130025 | B4: 5 | C4: Denmark | D4: 45086.96 | E4: Other | F4: Jeff Young | G4: 5739 | H4: =VLOOKUP(B4,'Customers (2)'!$A$1:$F$2501,2,0) -> Denmark | I4: =VLOOKUP(B4,'Customers (2)'!$A$1:$F$2501,3,0) -> M | J4: =VLOOKUP(B4,'Customers (2)'!$A$1:$F$2501,4,0) -> 81 | K4: =VLOOKUP(B4,'Customers (2)'!$A$1:$F$2501,5,0) -> A | L4: =VLOOKUP(B4,'Customers (2)'!$A$1:$F$2501,6,0) -> Senior | M4: =TEXT(D4,"MMMM") -> June | N4: =TEXT(D4,"dddd") -> Friday | O4: =TEXT(D4,"HH:mm:ss") -> 23:02:00 | P4: =HOUR(D4) -> 23 | Q4: =VLOOKUP(B4,'Analysis 1.3'!$AA$1:$AF$1454,5,FALSE) -> One time | R4: =VLOOKUP(B4,'Analysis 1.3'!$AA$1:$AF$1454,6,FALSE) -> Lost | S4: =VLOOKUP(B4,'Analysis 1.3'!$AA$1:$AF$1454,4,FALSE) -> 205.02222 | V4: Denmark | W4: =COUNTIFS($C$1:$C$2501,$V4,$E$1:$E$2501,W$1) -> 26 | X4: =COUNTIFS($C$1:$C$2501,$V4,$E$1:$E$2501,X$1) -> 11 | Y4: =COUNTIFS($C$1:$C$2501,$V4,$E$1:$E$2501,Y$1) -> 10 | Z4: =COUNTIFS($C$1:$C$2501,$V4,$E$1:$E$2501,Z$1) -> 19 | AA4: =COUNTIFS($C$1:$C$2501,$V4,$E$1:$E$2501,"") -> 0 | AC4: Female | AD4: =COUNTIF(I2:I2501, "F") -> 1276
A5: 10922 | B5: 7 | C5: Singapore | D5: 44945.94 | E5: App | F5: Kyung Yu | G5: 3157 | H5: =VLOOKUP(B5,'Customers (2)'!$A$1:$F$2501,2,0) -> Singapore | I5: =VLOOKUP(B5,'Customers (2)'!$A$1:$F$2501,3,0) -> M | J5: =VLOOKUP(B5,'Customers (2)'!$A$1:$F$2501,4,0) -> 76 | K5: =VLOOKUP(B5,'Customers (2)'!$A$1:$F$2501,5,0) -> A | L5: =VLOOKUP(B5,'Customers (2)'!$A$1:$F$2501,6,0) -> Senior | M5: =TEXT(D5,"MMMM") -> January | N5: =TEXT(D5,"dddd") -> Thursday | O5: =TEXT(D5,"HH:mm:ss") -> 22:33:00 | P5: =HOUR(D5) -> 22 | Q5: =VLOOKUP(B5,'Analysis 1.3'!$AA$1:$AF$1454,5,FALSE) -> One time | R5: =VLOOKUP(B5,'Analysis 1.3'!$AA$1:$AF$1454,6,FALSE) -> Lost | S5: =VLOOKUP(B5,'Analysis 1.3'!$AA$1:$AF$1454,4,FALSE) -> 346.04236 | V5: Singapore | W5: =COUNTIFS($C$1:$C$2501,$V5,$E$1:$E$2501,W$1) -> 27 | X5: =COUNTIFS($C$1:$C$2501,$V5,$E$1:$E$2501,X$1) -> 31 | Y5: =COUNTIFS($C$1:$C$2501,$V5,$E$1:$E$2501,Y$1) -> 20 | Z5: =COUNTIFS($C$1:$C$2501,$V5,$E$1:$E$2501,Z$1) -> 18 | AA5: =COUNTIFS($C$1:$C$2501,$V5,$E$1:$E$2501,"") -> 1
A6: 990832 | B6: 9 | C6: France | D6: 45137.012 | E6: Other | F6: Kwai Yu | G6: 8202 | H6: =VLOOKUP(B6,'Customers (2)'!$A$1:$F$2501,2,0) -> France | I6: =VLOOKUP(B6,'Customers (2)'!$A$1:$F$2501,3,0) -> F | J6: =VLOOKUP(B6,'Customers (2)'!$A$1:$F$2501,4,0) -> 75 | K6: =VLOOKUP(B6,'Customers (2)'!$A$1:$F$2501,5,0) -> A | L6: =VLOOKUP(B6,'Customers (2)'!$A$1:$F$2501,6,0) -> Senior | M6: =TEXT(D6,"MMMM") -> July | N6: =TEXT(D6,"dddd") -> Sunday | O6: =TEXT(D6,"HH:mm:ss") -> 00:18:00 | P6: =HOUR(D6) -> 0 | Q6: =VLOOKUP(B6,'Analysis 1.3'!$AA$1:$AF$1454,5,FALSE) -> Repeat | R6: =VLOOKUP(B6,'Analysis 1.3'!$AA$1:$AF$1454,6,FALSE) -> Passive | S6: =VLOOKUP(B6,'Analysis 1.3'!$AA$1:$AF$1454,4,FALSE) -> 91.938194 | V6: Norway | W6: =COUNTIFS($C$1:$C$2501,$V6,$E$1:$E$2501,W$1) -> 7 | X6: =COUNTIFS($C$1:$C$2501,$V6,$E$1:$E$2501,X$1) -> 11 | Y6: =COUNTIFS($C$1:$C$2501,$V6,$E$1:$E$2501,Y$1) -> 13 | Z6: =COUNTIFS($C$1:$C$2501,$V6,$E$1:$E$2501,Z$1) -> 9 | AA6: =COUNTIFS($C$1:$C$2501,$V6,$E$1:$E$2501,"") -> 0 | AB6: Website | AC6: =COUNTIF($E$1:$E$2501,"Whatsapp") -> 633
A7: 1004148 | B7: 9 | C7: France | D7: 45200.044 | E7: Whatsapp | F7: Adrian Huxley | G7: 9670 | H7: =VLOOKUP(B7,'Customers (2)'!$A$1:$F$2501,2,0) -> France | I7: =VLOOKUP(B7,'Customers (2)'!$A$1:$F$2501,3,0) -> F | J7: =VLOOKUP(B7,'Customers (2)'!$A$1:$F$2501,4,0) -> 75 | K7: =VLOOKUP(B7,'Customers (2)'!$A$1:$F$2501,5,0) -> A | L7: =VLOOKUP(B7,'Customers (2)'!$A$1:$F$2501,6,0) -> Senior | M7: =TEXT(D7,"MMMM") -> October | N7: =TEXT(D7,"dddd") -> Sunday | O7: =TEXT(D7,"HH:mm:ss") -> 01:03:00 | P7: =HOUR(D7) -> 1 | Q7: =VLOOKUP(B7,'Analysis 1.3'!$AA$1:$AF$1454,5,FALSE) -> Repeat | R7: =VLOOKUP(B7,'Analysis 1.3'!$AA$1:$AF$1454,6,FALSE) -> Passive | S7: =VLOOKUP(B7,'Analysis 1.3'!$AA$1:$AF$1454,4,FALSE) -> 91.938194 | V7: Spain | W7: =COUNTIFS($C$1:$C$2501,$V7,$E$1:$E$2501,W$1) -> 68 | X7: =COUNTIFS($C$1:$C$2501,$V7,$E$1:$E$2501,X$1) -> 65 | Y7: =COUNTIFS($C$1:$C$2501,$V7,$E$1:$E$2501,Y$1) -> 72 | Z7: =COUNTIFS($C$1:$C$2501,$V7,$E$1:$E$2501,Z$1) -> 59 | AA7: =COUNTIFS($C$1:$C$2501,$V7,$E$1:$E$2501,"") -> 4 | AB7: Whatsapp | AC7: =COUNTIF($E$1:$E$2501,"other") -> 591
A8: 213090 | B8: 10 | C8: Norway | D8: 45208.044 | E8: Other | F8: Jytte Petersen | G8: 9353 | H8: =VLOOKUP(B8,'Customers (2)'!$A$1:$F$2501,2,0) -> Norway | I8: =VLOOKUP(B8,'Customers (2)'!$A$1:$F$2501,3,0) -> F | J8: =VLOOKUP(B8,'Customers (2)'!$A$1:$F$2501,4,0) -> 32 | K8: =VLOOKUP(B8,'Customers (2)'!$A$1:$F$2501,5,0) -> A | L8: =VLOOKUP(B8,'Customers (2)'!$A$1:$F$2501,6,0) -> Young | M8: =TEXT(D8,"MMMM") -> October | N8: =TEXT(D8,"dddd") -> Monday | O8: =TEXT(D8,"HH:mm:ss") -> 01:03:00 | P8: =HOUR(D8) -> 1 | Q8: =VLOOKUP(B8,'Analysis 1.3'!$AA$1:$AF$1454,5,FALSE) -> One time | R8: =VLOOKUP(B8,'Analysis 1.3'!$AA$1:$AF$1454,6,FALSE) -> Passive | S8: =VLOOKUP(B8,'Analysis 1.3'!$AA$1:$AF$1454,4,FALSE) -> 83.938194 | V8: Germany | W8: =COUNTIFS($C$1:$C$2501,$V8,$E$1:$E$2501,W$1) -> 17 | X8: =COUNTIFS($C$1:$C$2501,$V8,$E$1:$E$2501,X$1) -> 11 | Y8: =COUNTIFS($C$1:$C$2501,$V8,$E$1:$E$2501,Y$1) -> 17 | Z8: =COUNTIFS($C$1:$C$2501,$V8,$E$1:$E$2501,Z$1) -> 13 | AA8: =COUNTIFS($C$1:$C$2501,$V8,$E$1:$E$2501,"") -> 0 | AB8: App | AC8: =COUNTIF($E$1:$E$2501,"app") -> 622
A9: 390509 | B9: 11 | C9: USA | D9: 45147.04 | E9: Other | F9: Paul Henriot | G9: 2754 | H9: =VLOOKUP(B9,'Customers (2)'!$A$1:$F$2501,2,0) -> USA | I9: =VLOOKUP(B9,'Customers (2)'!$A$1:$F$2501,3,0) -> F | J9: =VLOOKUP(B9,'Customers (2)'!$A$1:$F$2501,4,0) -> 82 | K9: =VLOOKUP(B9,'Customers (2)'!$A$1:$F$2501,5,0) -> A | L9: =VLOOKUP(B9,'Customers (2)'!$A$1:$F$2501,6,0) -> Senior | M9: =TEXT(D9,"MMMM") -> August | N9: =TEXT(D9,"dddd") -> Wednesday | O9: =TEXT(D9,"HH:mm:ss") -> 00:58:00 | P9: =HOUR(D9) -> 0 | Q9: =VLOOKUP(B9,'Analysis 1.3'!$AA$1:$AF$1454,5,FALSE) -> One time | R9: =VLOOKUP(B9,'Analysis 1.3'!$AA$1:$AF$1454,6,FALSE) -> Passive | S9: =VLOOKUP(B9,'Analysis 1.3'!$AA$1:$AF$1454,4,FALSE) -> 144.94167 | V9: Australia | W9: =COUNTIFS($C$1:$C$2501,$V9,$E$1:$E$2501,W$1) -> 50 | X9: =COUNTIFS($C$1:$C$2501,$V9,$E$1:$E$2501,X$1) -> 58 | Y9: =COUNTIFS($C$1:$C$2501,$V9,$E$1:$E$2501,Y$1) -> 52 | Z9: =COUNTIFS($C$1:$C$2501,$V9,$E$1:$E$2501,Z$1) -> 38 | AA9: =COUNTIFS($C$1:$C$2501,$V9,$E$1:$E$2501,"") -> 0 | AB9: Other | AC9: =COUNTIF($E$1:$E$2501,"Website") -> 637
A10: 510478 | B10: 12 | C10: Spain | D10: 44998.968 | E10: App | F10: Sue King | G10: 4788 | H10: =VLOOKUP(B10,'Customers (2)'!$A$1:$F$2501,2,0) -> Spain | I10: =VLOOKUP(B10,'Customers (2)'!$A$1:$F$2501,3,0) -> F | J10: =VLOOKUP(B10,'Customers (2)'!$A$1:$F$2501,4,0) -> 65 | K10: =VLOOKUP(B10,'Customers (2)'!$A$1:$F$2501,5,0) -> A | L10: =VLOOKUP(B10,'Customers (2)'!$A$1:$F$2501,6,0) -> Senior | M10: =TEXT(D10,"MMMM") -> March | N10: =TEXT(D10,"dddd") -> Monday | O10: =TEXT(D10,"HH:mm:ss") -> 23:14:00 | P10: =HOUR(D10) -> 23 | Q10: =VLOOKUP(B10,'Analysis 1.3'!$AA$1:$AF$1454,5,FALSE) -> Repeat | R10: =VLOOKUP(B10,'Analysis 1.3'!$AA$1:$AF$1454,6,FALSE) -> Passive | S10: =VLOOKUP(B10,'Analysis 1.3'!$AA$1:$AF$1454,4,FALSE) -> 84.942361 | V10: Finland | W10: =COUNTIFS($C$1:$C$2501,$V10,$E$1:$E$2501,W$1) -> 12 | X10: =COUNTIFS($C$1:$C$2501,$V10,$E$1:$E$2501,X$1) -> 18 | Y10: =COUNTIFS($C$1:$C$2501,$V10,$E$1:$E$2501,Y$1) -> 15 | Z10: =COUNTIFS($C$1:$C$2501,$V10,$E$1:$E$2501,Z$1) -> 20 | AA10: =COUNTIFS($C$1:$C$2501,$V10,$E$1:$E$2501,"") -> 1 | AB10: Blanks | AC10: =COUNTIF($E$1:$E$2501,"") -> 17
A11: 537514 | B11: 12 | C11: Spain | D11: 45207.04 | F11: Julie Brown | G11: 8747 | H11: =VLOOKUP(B11,'Customers (2)'!$A$1:$F$2501,2,0) -> Spain | I11: =VLOOKUP(B11,'Customers (2)'!$A$1:$F$2501,3,0) -> F | J11: =VLOOKUP(B11,'Customers (2)'!$A$1:$F$2501,4,0) -> 65 | K11: =VLOOKUP(B11,'Customers (2)'!$A$1:$F$2501,5,0) -> A | L11: =VLOOKUP(B11,'Customers (2)'!$A$1:$F$2501,6,0) -> Senior | M11: =TEXT(D11,"MMMM") -> October | N11: =TEXT(D11,"dddd") -> Sunday | O11: =TEXT(D11,"HH:mm:ss") -> 00:57:00 | P11: =HOUR(D11) -> 0 | Q11: =VLOOKUP(B11,'Analysis 1.3'!$AA$1:$AF$1454,5,FALSE) -> Repeat | R11: =VLOOKUP(B11,'Analysis 1.3'!$AA$1:$AF$1454,6,FALSE) -> Passive | S11: =VLOOKUP(B11,'Analysis 1.3'!$AA$1:$AF$1454,4,FALSE) -> 84.942361 | V11: Italy | W11: =COUNTIFS($C$1:$C$2501,$V11,$E$1:$E$2501,W$1) -> 39 | X11: =COUNTIFS($C$1:$C$2501,$V11,$E$1:$E$2501,X$1) -> 19 | Y11: =COUNTIFS($C$1:$C$2501,$V11,$E$1:$E$2501,Y$1) -> 18 | Z11: =COUNTIFS($C$1:$C$2501,$V11,$E$1:$E$2501,Z$1) -> 36 | AA11: =COUNTIFS($C$1:$C$2501,$V11,$E$1:$E$2501,"") -> 0
A12: 1033877 | B12: 13 | C12: Spain | D12: 44983.071 | E12: Whatsapp | F12: Victoria Ashworth | G12: 4612 | H12: =VLOOKUP(B12,'Customers (2)'!$A$1:$F$2501,2,0) -> Spain | I12: =VLOOKUP(B12,'Customers (2)'!$A$1:$F$2501,3,0) -> F | J12: =VLOOKUP(B12,'Customers (2)'!$A$1:$F$2501,4,0) -> 84 | K12: =VLOOKUP(B12,'Customers (2)'!$A$1:$F$2501,5,0) -> A | L12: =VLOOKUP(B12,'Customers (2)'!$A$1:$F$2501,6,0) -> Senior | M12: =TEXT(D12,"MMMM") -> February | N12: =TEXT(D12,"dddd") -> Sunday | O12: =TEXT(D12,"HH:mm:ss") -> 01:42:00 | P12: =HOUR(D12) -> 1 | Q12: =VLOOKUP(B12,'Analysis 1.3'!$AA$1:$AF$1454,5,FALSE) -> One time | R12: =VLOOKUP(B12,'Analysis 1.3'!$AA$1:$AF$1454,6,FALSE) -> Lost | S12: =VLOOKUP(B12,'Analysis 1.3'!$AA$1:$AF$1454,4,FALSE) -> 308.91111 | V12: India | W12: =COUNTIFS($C$1:$C$2501,$V12,$E$1:$E$2501,W$1) -> 70 | X12: =COUNTIFS($C$1:$C$2501,$V12,$E$1:$E$2501,X$1) -> 66 | Y12: =COUNTIFS($C$1:$C$2501,$V12,$E$1:$E$2501,Y$1) -> 74 | Z12: =COUNTIFS($C$1:$C$2501,$V12,$E$1:$E$2501,Z$1) -> 70 | AA12: =COUNTIFS($C$1:$C$2501,$V12,$E$1:$E$2501,"") -> 1
A13: 675864 | B13: 15 | C13: Germany | D13: 45159.008 | E13: Website | F13: Anna O'Hara | G13: 9493 | H13: =VLOOKUP(B13,'Customers (2)'!$A$1:$F$2501,2,0) -> Germany | I13: =VLOOKUP(B13,'Customers (2)'!$A$1:$F$2501,3,0) -> F | J13: =VLOOKUP(B13,'Customers (2)'!$A$1:$F$2501,4,0) -> 48 | K13: =VLOOKUP(B13,'Customers (2)'!$A$1:$F$2501,5,0) -> A | L13: =VLOOKUP(B13,'Customers (2)'!$A$1:$F$2501,6,0) -> Middle | M13: =TEXT(D13,"MMMM") -> August | N13: =TEXT(D13,"dddd") -> Monday | O13: =TEXT(D13,"HH:mm:ss") -> 00:12:00 | P13: =HOUR(D13) -> 0 | Q13: =VLOOKUP(B13,'Analysis 1.3'!$AA$1:$AF$1454,5,FALSE) -> One time | R13: =VLOOKUP(B13,'Analysis 1.3'!$AA$1:$AF$1454,6,FALSE) -> Passive | S13: =VLOOKUP(B13,'Analysis 1.3'!$AA$1:$AF$1454,4,FALSE) -> 132.97361 | V13: Ireland | W13: =COUNTIFS($C$1:$C$2501,$V13,$E$1:$E$2501,W$1) -> 5 | X13: =COUNTIFS($C$1:$C$2501,$V13,$E$1:$E$2501,X$1) -> 5 | Y13: =COUNTIFS($C$1:$C$2501,$V13,$E$1:$E$2501,Y$1) -> 5 | Z13: =COUNTIFS($C$1:$C$2501,$V13,$E$1:$E$2501,Z$1) -> 5 | AA13: =COUNTIFS($C$1:$C$2501,$V13,$E$1:$E$2501,"") -> 0
A14: 844238 | B14: 16 | C14: Norway | D14: 45131.028 | E14: App | F14: Diego Freyre | G14: 4887 | H14: =VLOOKUP(B14,'Customers (2)'!$A$1:$F$2501,2,0) -> Norway | I14: =VLOOKUP(B14,'Customers (2)'!$A$1:$F$2501,3,0) -> F | J14: =VLOOKUP(B14,'Customers (2)'!$A$1:$F$2501,4,0) -> 81 | K14: =VLOOKUP(B14,'Customers (2)'!$A$1:$F$2501,5,0) -> A | L14: =VLOOKUP(B14,'Customers (2)'!$A$1:$F$2501,6,0) -> Senior | M14: =TEXT(D14,"MMMM") -> July | N14: =TEXT(D14,"dddd") -> Monday | O14: =TEXT(D14,"HH:mm:ss") -> 00:40:00 | P14: =HOUR(D14) -> 0 | Q14: =VLOOKUP(B14,'Analysis 1.3'!$AA$1:$AF$1454,5,FALSE) -> Repeat | R14: =VLOOKUP(B14,'Analysis 1.3'!$AA$1:$AF$1454,6,FALSE) -> Passive | S14: =VLOOKUP(B14,'Analysis 1.3'!$AA$1:$AF$1454,4,FALSE) -> 160.95417 | V14: Austria | W14: =COUNTIFS($C$1:$C$2501,$V14,$E$1:$E$2501,W$1) -> 12 | X14: =COUNTIFS($C$1:$C$2501,$V14,$E$1:$E$2501,X$1) -> 10 | Y14: =COUNTIFS($C$1:$C$2501,$V14,$E$1:$E$2501,Y$1) -> 9 | Z14: =COUNTIFS($C$1:$C$2501,$V14,$E$1:$E$2501,Z$1) -> 12 | AA14: =COUNTIFS($C$1:$C$2501,$V14,$E$1:$E$2501,"") -> 0
A15: 1132855 | B15: 16 | C15: Norway | D15: 45097.083 | E15: App | F15: Jeff Young | G15: 4518 | H15: =VLOOKUP(B15,'Customers (2)'!$A$1:$F$2501,2,0) -> Norway | I15: =VLOOKUP(B15,'Customers (2)'!$A$1:$F$2501,3,0) -> F | J15: =VLOOKUP(B15,'Customers (2)'!$A$1:$F$2501,4,0) -> 81 | K15: =VLOOKUP(B15,'Customers (2)'!$A$1:$F$2501,5,0) -> A | L15: =VLOOKUP(B15,'Customers (2)'!$A$1:$F$2501,6,0) -> Senior | M15: =TEXT(D15,"MMMM") -> June | N15: =TEXT(D15,"dddd") -> Tuesday | O15: =TEXT(D15,"HH:mm:ss") -> 02:00:00 | P15: =HOUR(D15) -> 2 | Q15: =VLOOKUP(B15,'Analysis 1.3'!$AA$1:$AF$1454,5,FALSE) -> Repeat | R15: =VLOOKUP(B15,'Analysis 1.3'!$AA$1:$AF$1454,6,FALSE) -> Passive | S15: =VLOOKUP(B15,'Analysis 1.3'!$AA$1:$AF$1454,4,FALSE) -> 160.95417 | V15: Switzerland | W15: =COUNTIFS($C$1:$C$2501,$V15,$E$1:$E$2501,W$1) -> 7 | X15: =COUNTIFS($C$1:$C$2501,$V15,$E$1:$E$2501,X$1) -> 9 | Y15: =COUNTIFS($C$1:$C$2501,$V15,$E$1:$E$2501,Y$1) -> 11 | Z15: =COUNTIFS($C$1:$C$2501,$V15,$E$1:$E$2501,Z$1) -> 9 | AA15: =COUNTIFS($C$1:$C$2501,$V15,$E$1:$E$2501,"") -> 0
A16: 1547057 | B16: 18 | C16: USA | D16: 45060.031 | E16: Other | F16: Akiko Shimamura | G16: 9727 | H16: =VLOOKUP(B16,'Customers (2)'!$A$1:$F$2501,2,0) -> USA | I16: =VLOOKUP(B16,'Customers (2)'!$A$1:$F$2501,3,0) -> F | J16: =VLOOKUP(B16,'Customers (2)'!$A$1:$F$2501,4,0) -> 85 | K16: =VLOOKUP(B16,'Customers (2)'!$A$1:$F$2501,5,0) -> A | L16: =VLOOKUP(B16,'Customers (2)'!$A$1:$F$2501,6,0) -> Senior | M16: =TEXT(D16,"MMMM") -> May | N16: =TEXT(D16,"dddd") -> Sunday | O16: =TEXT(D16,"HH:mm:ss") -> 00:44:00 | P16: =HOUR(D16) -> 0 | Q16: =VLOOKUP(B16,'Analysis 1.3'!$AA$1:$AF$1454,5,FALSE) -> One time | R16: =VLOOKUP(B16,'Analysis 1.3'!$AA$1:$AF$1454,6,FALSE) -> Lost | S16: =VLOOKUP(B16,'Analysis 1.3'!$AA$1:$AF$1454,4,FALSE) -> 231.95139 | W16: =SUM(W2:W15) -> 635 | X16: =SUM(X2:X15) -> 631 | Y16: =SUM(Y2:Y15) -> 621 | Z16: =SUM(Z2:Z15) -> 589 | AA16: =SUM(AA2:AA15) -> 17
A17: 3971 | B17: 20 | C17: USA | D17: 45225.966 | E17: Website | F17: Julie Brown | G17: 5545 | H17: =VLOOKUP(B17,'Customers (2)'!$A$1:$F$2501,2,0) -> USA | I17: =VLOOKUP(B17,'Customers (2)'!$A$1:$F$2501,3,0) -> F | J17: =VLOOKUP(B17,'Customers (2)'!$A$1:$F$2501,4,0) -> 38 | K17: =VLOOKUP(B17,'Customers (2)'!$A$1:$F$2501,5,0) -> A | L17: =VLOOKUP(B17,'Customers (2)'!$A$1:$F$2501,6,0) -> Middle | M17: =TEXT(D17,"MMMM") -> October | N17: =TEXT(D17,"dddd") -> Thursday | O17: =TEXT(D17,"HH:mm:ss") -> 23:11:00 | P17: =HOUR(D17) -> 23 | Q17: =VLOOKUP(B17,'Analysis 1.3'!$AA$1:$AF$1454,5,FALSE) -> Repeat | R17: =VLOOKUP(B17,'Analysis 1.3'!$AA$1:$AF$1454,6,FALSE) -> Recent | S17: =VLOOKUP(B17,'Analysis 1.3'!$AA$1:$AF$1454,4,FALSE) -> 66.015972
A18: 1104509 | B18: 20 | C18: USA | D18: 45073.06 | E18: Other | F18: Janine Labrune | G18: 5599 | H18: =VLOOKUP(B18,'Customers (2)'!$A$1:$F$2501,2,0) -> USA | I18: =VLOOKUP(B18,'Customers (2)'!$A$1:$F$2501,3,0) -> F | J18: =VLOOKUP(B18,'Customers (2)'!$A$1:$F$2501,4,0) -> 38 | K18: =VLOOKUP(B18,'Customers (2)'!$A$1:$F$2501,5,0) -> A | L18: =VLOOKUP(B18,'Customers (2)'!$A$1:$F$2501,6,0) -> Middle | M18: =TEXT(D18,"MMMM") -> May | N18: =TEXT(D18,"dddd") -> Saturday | O18: =TEXT(D18,"HH:mm:ss") -> 01:26:00 | P18: =HOUR(D18) -> 1 | Q18: =VLOOKUP(B18,'Analysis 1.3'!$AA$1:$AF$1454,5,FALSE) -> Repeat | R18: =VLOOKUP(B18,'Analysis 1.3'!$AA$1:$AF$1454,6,FALSE) -> Recent | S18: =VLOOKUP(B18,'Analysis 1.3'!$AA$1:$AF$1454,4,FALSE) -> 66.015972
A19: 813036 | B19: 22 | C19: Spain | D19: 45248.945 | E19: App | F19: Thomas Hardy | G19: 5132 | H19: =VLOOKUP(B19,'Customers (2)'!$A$1:$F$2501,2,0) -> Spain | I19: =VLOOKUP(B19,'Customers (2)'!$A$1:$F$2501,3,0) -> F | J19: =VLOOKUP(B19,'Customers (2)'!$A$1:$F$2501,4,0) -> 78 | K19: =VLOOKUP(B19,'Customers (2)'!$A$1:$F$2501,5,0) -> A | L19: =VLOOKUP(B19,'Customers (2)'!$A$1:$F$2501,6,0) -> Senior | M19: =TEXT(D19,"MMMM") -> November | N19: =TEXT(D19,"dddd") -> Saturday | O19: =TEXT(D19,"HH:mm:ss") -> 22:41:00 | P19: =HOUR(D19) -> 22 | Q19: =VLOOKUP(B19,'Analysis 1.3'!$AA$1:$AF$1454,5,FALSE) -> One time | R19: =VLOOKUP(B19,'Analysis 1.3'!$AA$1:$AF$1454,6,FALSE) -> Recent | S19: =VLOOKUP(B19,'Analysis 1.3'!$AA$1:$AF$1454,4,FALSE) -> 43.036806
A20: 1036642 | B20: 24 | C20: Spain | D20: 45049.058 | E20: Other | F20: Diego Freyre | G20: 9159 | H20: =VLOOKUP(B20,'Customers (2)'!$A$1:$F$2501,2,0) -> Spain | I20: =VLOOKUP(B20,'Customers (2)'!$A$1:$F$2501,3,0) -> F | J20: =VLOOKUP(B20,'Customers (2)'!$A$1:$F$2501,4,0) -> 47 | K20: =VLOOKUP(B20,'Customers (2)'!$A$1:$F$2501,5,0) -> A | L20: =VLOOKUP(B20,'Customers (2)'!$A$1:$F$2501,6,0) -> Middle | M20: =TEXT(D20,"MMMM") -> May | N20: =TEXT(D20,"dddd") -> Wednesday | O20: =TEXT(D20,"HH:mm:ss") -> 01:23:00 | P20: =HOUR(D20) -> 1 | Q20: =VLOOKUP(B20,'Analysis 1.3'!$AA$1:$AF$1454,5,FALSE) -> One time | R20: =VLOOKUP(B20,'Analysis 1.3'!$AA$1:$AF$1454,6,FALSE) -> Lost | S20: =VLOOKUP(B20,'Analysis 1.3'!$AA$1:$AF$1454,4,FALSE) -> 242.92431
A21: 1288792 | B21: 25 | C21: USA | D21: 45265.07 | E21: Whatsapp | F21: Anna O'Hara | G21: 3516 | H21: =VLOOKUP(B21,'Customers (2)'!$A$1:$F$2501,2,0) -> USA | I21: =VLOOKUP(B21,'Customers (2)'!$A$1:$F$2501,3,0) -> M | J21: =VLOOKUP(B21,'Customers (2)'!$A$1:$F$2501,4,0) -> 59 | K21: =VLOOKUP(B21,'Customers (2)'!$A$1:$F$2501,5,0) -> A | L21: =VLOOKUP(B21,'Customers (2)'!$A$1:$F$2501,6,0) -> Middle | M21: =TEXT(D21,"MMMM") -> December | N21: =TEXT(D21,"dddd") -> Tuesday | O21: =TEXT(D21,"HH:mm:ss") -> 01:41:00 | P21: =HOUR(D21) -> 1 | Q21: =VLOOKUP(B21,'Analysis 1.3'!$AA$1:$AF$1454,5,FALSE) -> One time | R21: =VLOOKUP(B21,'Analysis 1.3'!$AA$1:$AF$1454,6,FALSE) -> Recent | S21: =VLOOKUP(B21,'Analysis 1.3'!$AA$1:$AF$1454,4,FALSE) -> 26.911806
A22: 13586 | B22: 26 | C22: France | D22: 44949.012 | E22: App | F22: Adrian Huxley | G22: 321 | H22: =VLOOKUP(B22,'Customers (2)'!$A$1:$F$2501,2,0) -> France | I22: =VLOOKUP(B22,'Customers (2)'!$A$1:$F$2501,3,0) -> M | J22: =VLOOKUP(B22,'Customers (2)'!$A$1:$F$2501,4,0) -> 27 | K22: =VLOOKUP(B22,'Customers (2)'!$A$1:$F$2501,5,0) -> A | L22: =VLOOKUP(B22,'Customers (2)'!$A$1:$F$2501,6,0) -> Young | M22: =TEXT(D22,"MMMM") -> January | N22: =TEXT(D22,"dddd") -> Monday | O22: =TEXT(D22,"HH:mm:ss") -> 00:17:00 | P22: =HOUR(D22) -> 0 | Q22: =VLOOKUP(B22,'Analysis 1.3'!$AA$1:$AF$1454,5,FALSE) -> Repeat | R22: =VLOOKUP(B22,'Analysis 1.3'!$AA$1:$AF$1454,6,FALSE) -> Passive | S22: =VLOOKUP(B22,'Analysis 1.3'!$AA$1:$AF$1454,4,FALSE) -> 175.98403
A23: 675163 | B23: 26 | C23: France | D23: 45100.94 | E23: Whatsapp | F23: Annette Roulet | G23: 8499 | H23: =VLOOKUP(B23,'Customers (2)'!$A$1:$F$2501,2,0) -> France | I23: =VLOOKUP(B23,'Customers (2)'!$A$1:$F$2501,3,0) -> M | J23: =VLOOKUP(B23,'Customers (2)'!$A$1:$F$2501,4,0) -> 27 | K23: =VLOOKUP(B23,'Customers (2)'!$A$1:$F$2501,5,0) -> A | L23: =VLOOKUP(B23,'Customers (2)'!$A$1:$F$2501,6,0) -> Young | M23: =TEXT(D23,"MMMM") -> June | N23: =TEXT(D23,"dddd") -> Friday | O23: =TEXT(D23,"HH:mm:ss") -> 22:33:00 | P23: =HOUR(D23) -> 22 | Q23: =VLOOKUP(B23,'Analysis 1.3'!$AA$1:$AF$1454,5,FALSE) -> Repeat | R23: =VLOOKUP(B23,'Analysis 1.3'!$AA$1:$AF$1454,6,FALSE) -> Passive | S23: =VLOOKUP(B23,'Analysis 1.3'!$AA$1:$AF$1454,4,FALSE) -> 175.98403
A24: 1453632 | B24: 26 | C24: France | D24: 45071.034 | E24: App | F24: Diego Freyre | G24: 1681 | H24: =VLOOKUP(B24,'Customers (2)'!$A$1:$F$2501,2,0) -> France | I24: =VLOOKUP(B24,'Customers (2)'!$A$1:$F$2501,3,0) -> M | J24: =VLOOKUP(B24,'Customers (2)'!$A$1:$F$2501,4,0) -> 27 | K24: =VLOOKUP(B24,'Customers (2)'!$A$1:$F$2501,5,0) -> A | L24: =VLOOKUP(B24,'Customers (2)'!$A$1:$F$2501,6,0) -> Young | M24: =TEXT(D24,"MMMM") -> May | N24: =TEXT(D24,"dddd") -> Thursday | O24: =TEXT(D24,"HH:mm:ss") -> 00:49:00 | P24: =HOUR(D24) -> 0 | Q24: =VLOOKUP(B24,'Analysis 1.3'!$AA$1:$AF$1454,5,FALSE) -> Repeat | R24: =VLOOKUP(B24,'Analysis 1.3'!$AA$1:$AF$1454,6,FALSE) -> Passive | S24: =VLOOKUP(B24,'Analysis 1.3'!$AA$1:$AF$1454,4,FALSE) -> 175.98403
A25: 1480087 | B25: 26 | C25: France | D25: 45115.998 | E25: Website | F25: Steve Frick | G25: 9335 | H25: =VLOOKUP(B25,'Customers (2)'!$A$1:$F$2501,2,0) -> France | I25: =VLOOKUP(B25,'Customers (2)'!$A$1:$F$2501,3,0) -> M | J25: =VLOOKUP(B25,'Customers (2)'!$A$1:$F$2501,4,0) -> 27 | K25: =VLOOKUP(B25,'Customers (2)'!$A$1:$F$2501,5,0) -> A | L25: =VLOOKUP(B25,'Customers (2)'!$A$1:$F$2501,6,0) -> Young | M25: =TEXT(D25,"MMMM") -> July | N25: =TEXT(D25,"dddd") -> Saturday | O25: =TEXT(D25,"HH:mm:ss") -> 23:57:00 | P25: =HOUR(D25) -> 23 | Q25: =VLOOKUP(B25,'Analysis 1.3'!$AA$1:$AF$1454,5,FALSE) -> Repeat | R25: =VLOOKUP(B25,'Analysis 1.3'!$AA$1:$AF$1454,6,FALSE) -> Passive | S25: =VLOOKUP(B25,'Analysis 1.3'!$AA$1:$AF$1454,4,FALSE) -> 175.98403
A26: 257849 | B26: 27 | C26: USA | D26: 45284.033 | E26: Other | F26: Henriette Pfalzheim | G26: 1534 | H26: =VLOOKUP(B26,'Customers (2)'!$A$1:$F$2501,2,0) -> USA | I26: =VLOOKUP(B26,'Customers (2)'!$A$1:$F$2501,3,0) -> F | J26: =VLOOKUP(B26,'Customers (2)'!$A$1:$F$2501,4,0) -> 66 | K26: =VLOOKUP(B26,'Customers (2)'!$A$1:$F$2501,5,0) -> A | L26: =VLOOKUP(B26,'Customers (2)'!$A$1:$F$2501,6,0) -> Senior | M26: =TEXT(D26,"MMMM") -> December | N26: =TEXT(D26,"dddd") -> Sunday | O26: =TEXT(D26,"HH:mm:ss") -> 00:47:00 | P26: =HOUR(D26) -> 0 | Q26: =VLOOKUP(B26,'Analysis 1.3'!$AA$1:$AF$1454,5,FALSE) -> Repeat | R26: =VLOOKUP(B26,'Analysis 1.3'!$AA$1:$AF$1454,6,FALSE) -> Recent | S26: =VLOOKUP(B26,'Analysis 1.3'!$AA$1:$AF$1454,4,FALSE) -> 7.9493056
A27: 531173 | B27: 27 | C27: USA | D27: 45146.083 | E27: App | F27: Mary Saveley | G27: 9787 | H27: =VLOOKUP(B27,'Customers (2)'!$A$1:$F$2501,2,0) -> USA | I27: =VLOOKUP(B27,'Customers (2)'!$A$1:$F$2501,3,0) -> F | J27: =VLOOKUP(B27,'Customers (2)'!$A$1:$F$2501,4,0) -> 66 | K27: =VLOOKUP(B27,'Customers (2)'!$A$1:$F$2501,5,0) -> A | L27: =VLOOKUP(B27,'Customers (2)'!$A$1:$F$2501,6,0) -> Senior | M27: =TEXT(D27,"MMMM") -> August | N27: =TEXT(D27,"dddd") -> Tuesday | O27: =TEXT(D27,"HH:mm:ss") -> 02:00:00 | P27: =HOUR(D27) -> 2 | Q27: =VLOOKUP(B27,'Analysis 1.3'!$AA$1:$AF$1454,5,FALSE) -> Repeat | R27: =VLOOKUP(B27,'Analysis 1.3'!$AA$1:$AF$1454,6,FALSE) -> Recent | S27: =VLOOKUP(B27,'Analysis 1.3'!$AA$1:$AF$1454,4,FALSE) -> 7.9493056
A28: 668693 | B28: 27 | C28: USA | D28: 44936.966 | E28: Whatsapp | F28: Victoria Ashworth | G28: 3654 | H28: =VLOOKUP(B28,'Customers (2)'!$A$1:$F$2501,2,0) -> USA | I28: =VLOOKUP(B28,'Customers (2)'!$A$1:$F$2501,3,0) -> F | J28: =VLOOKUP(B28,'Customers (2)'!$A$1:$F$2501,4,0) -> 66 | K28: =VLOOKUP(B28,'Customers (2)'!$A$1:$F$2501,5,0) -> A | L28: =VLOOKUP(B28,'Customers (2)'!$A$1:$F$2501,6,0) -> Senior | M28: =TEXT(D28,"MMMM") -> January | N28: =TEXT(D28,"dddd") -> Tuesday | O28: =TEXT(D28,"HH:mm:ss") -> 23:11:00 | P28: =HOUR(D28) -> 23 | Q28: =VLOOKUP(B28,'Analysis 1.3'!$AA$1:$AF$1454,5,FALSE) -> Repeat | R28: =VLOOKUP(B28,'Analysis 1.3'!$AA$1:$AF$1454,6,FALSE) -> Recent | S28: =VLOOKUP(B28,'Analysis 1.3'!$AA$1:$AF$1454,4,FALSE) -> 7.9493056
... A35: 538560 | B35: 31 | C35: USA | D35: 45231.015 | E35: App | F35: Diego Freyre | G35: 9928 | H35: =VLOOKUP(B35,'Customers (2)'!$A$1:$F$2501,2,0) -> USA | I35: =VLOOKUP(B35,'Customers (2)'!$A$1:$F$2501,3,0) -> M | J35: =VLOOKUP(B35,'Customers (2)'!$A$1:$F$2501,4,0) -> 22 | K35: =VLOOKUP(B35,'Customers (2)'!$A$1:$F$2501,5,0) -> A | L35: =VLOOKUP(B35,'Customers (2)'!$A$1:$F$2501,6,0) -> Young | M35: =TEXT(D35,"MMMM") -> November | N35: =TEXT(D35,"dddd") -> Wednesday | O35: =TEXT(D35,"HH:mm:ss") -> 00:21:00 | P35: =HOUR(D35) -> 0 | Q35: =VLOOKUP(B35,'Analysis 1.3'!$AA$1:$AF$1454,5,FALSE) -> Repeat | R35: =VLOOKUP(B35,'Analysis 1.3'!$AA$1:$AF$1454,6,FALSE) -> Recent | S35: =VLOOKUP(B35,'Analysis 1.3'!$AA$1:$AF$1454,4,FALSE) -> 60.967361
A36: 552420 | B36: 31 | C36: USA | D36: 45131.981 | E36: Other | F36: Daniel Da Cunha | G36: 3937 | H36: =VLOOKUP(B36,'Customers (2)'!$A$1:$F$2501,2,0) -> USA | I36: =VLOOKUP(B36,'Customers (2)'!$A$1:$F$2501,3,0) -> M | J36: =VLOOKUP(B36,'Customers (2)'!$A$1:$F$2501,4,0) -> 22 | K36: =VLOOKUP(B36,'Customers (2)'!$A$1:$F$2501,5,0) -> A | L36: =VLOOKUP(B36,'Customers (2)'!$A$1:$F$2501,6,0) -> Young | M36: =TEXT(D36,"MMMM") -> July | N36: =TEXT(D36,"dddd") -> Monday | O36: =TEXT(D36,"HH:mm:ss") -> 23:33:00 | P36: =HOUR(D36) -> 23 | Q36: =VLOOKUP(B36,'Analysis 1.3'!$AA$1:$AF$1454,5,FALSE) -> Repeat | R36: =VLOOKUP(B36,'Analysis 1.3'!$AA$1:$AF$1454,6,FALSE) -> Recent | S36: =VLOOKUP(B36,'Analysis 1.3'!$AA$1:$AF$1454,4,FALSE) -> 60.967361 | AF36: Q1 | AG36: =QUARTILE(J2:J2501,1) -> 35
A37: 597539 | B37: 31 | C37: USA | D37: 45161.051 | E37: Whatsapp | F37: Paolo Accorti | G37: 6892 | H37: =VLOOKUP(B37,'Customers (2)'!$A$1:$F$2501,2,0) -> USA | I37: =VLOOKUP(B37,'Customers (2)'!$A$1:$F$2501,3,0) -> M | J37: =VLOOKUP(B37,'Customers (2)'!$A$1:$F$2501,4,0) -> 22 | K37: =VLOOKUP(B37,'Customers (2)'!$A$1:$F$2501,5,0) -> A | L37: =VLOOKUP(B37,'Customers (2)'!$A$1:$F$2501,6,0) -> Young | M37: =TEXT(D37,"MMMM") -> August | N37: =TEXT(D37,"dddd") -> Wednesday | O37: =TEXT(D37,"HH:mm:ss") -> 01:13:00 | P37: =HOUR(D37) -> 1 | Q37: =VLOOKUP(B37,'Analysis 1.3'!$AA$1:$AF$1454,5,FALSE) -> Repeat | R37: =VLOOKUP(B37,'Analysis 1.3'!$AA$1:$AF$1454,6,FALSE) -> Recent | S37: =VLOOKUP(B37,'Analysis 1.3'!$AA$1:$AF$1454,4,FALSE) -> 60.967361 | W37: Q1 | X37: =QUARTILE(G2:G2501,1) -> 2364 | AF37: Q3 | AG37: =QUARTILE(J2:J2501,3) -> 71
A38: 1546512 | B38: 33 | C38: Spain | D38: 45284.039 | F38: Valarie Nelson | G38: 9521 | H38: =VLOOKUP(B38,'Customers (2)'!$A$1:$F$2501,2,0) -> Spain | I38: =VLOOKUP(B38,'Customers (2)'!$A$1:$F$2501,3,0) -> M | J38: =VLOOKUP(B38,'Customers (2)'!$A$1:$F$2501,4,0) -> 53 | K38: =VLOOKUP(B38,'Customers (2)'!$A$1:$F$2501,5,0) -> A | L38: =VLOOKUP(B38,'Customers (2)'!$A$1:$F$2501,6,0) -> Middle | M38: =TEXT(D38,"MMMM") -> December | N38: =TEXT(D38,"dddd") -> Sunday | O38: =TEXT(D38,"HH:mm:ss") -> 00:56:00 | P38: =HOUR(D38) -> 0 | Q38: =VLOOKUP(B38,'Analysis 1.3'!$AA$1:$AF$1454,5,FALSE) -> One time | R38: =VLOOKUP(B38,'Analysis 1.3'!$AA$1:$AF$1454,6,FALSE) -> Recent | S38: =VLOOKUP(B38,'Analysis 1.3'!$AA$1:$AF$1454,4,FALSE) -> 7.9430556 | W38: Q3 | X38: =QUARTILE(G2:G2501,3) -> 7439.25 | AF38: IQR | AG38: =AG37-AG36 -> 36
A39: 1617524 | B39: 34 | C39: Australia | D39: 44968.988 | E39: Other | F39: Valarie Nelson | G39: 1527 | H39: =VLOOKUP(B39,'Customers (2)'!$A$1:$F$2501,2,0) -> Australia | I39: =VLOOKUP(B39,'Customers (2)'!$A$1:$F$2501,3,0) -> F | J39: =VLOOKUP(B39,'Customers (2)'!$A$1:$F$2501,4,0) -> 20 | K39: =VLOOKUP(B39,'Customers (2)'!$A$1:$F$2501,5,0) -> A | L39: =VLOOKUP(B39,'Customers (2)'!$A$1:$F$2501,6,0) -> Young | M39: =TEXT(D39,"MMMM") -> February | N39: =TEXT(D39,"dddd") -> Saturday | O39: =TEXT(D39,"HH:mm:ss") -> 23:42:00 | P39: =HOUR(D39) -> 23 | Q39: =VLOOKUP(B39,'Analysis 1.3'!$AA$1:$AF$1454,5,FALSE) -> One time | R39: =VLOOKUP(B39,'Analysis 1.3'!$AA$1:$AF$1454,6,FALSE) -> Lost | S39: =VLOOKUP(B39,'Analysis 1.3'!$AA$1:$AF$1454,4,FALSE) -> 322.99444 | W39: IQR | X39: =X38-X37 -> 5075.25
A40: 604405 | B40: 36 | C40: USA | D40: 45238.037 | E40: Website | F40: Catherine Dewey | G40: 6944 | H40: =VLOOKUP(B40,'Customers (2)'!$A$1:$F$2501,2,0) -> USA | I40: =VLOOKUP(B40,'Customers (2)'!$A$1:$F$2501,3,0) -> M | J40: =VLOOKUP(B40,'Customers (2)'!$A$1:$F$2501,4,0) -> 63 | K40: =VLOOKUP(B40,'Customers (2)'!$A$1:$F$2501,5,0) -> A | L40: =VLOOKUP(B40,'Customers (2)'!$A$1:$F$2501,6,0) -> Senior | M40: =TEXT(D40,"MMMM") -> November | N40: =TEXT(D40,"dddd") -> Wednesday | O40: =TEXT(D40,"HH:mm:ss") -> 00:53:00 | P40: =HOUR(D40) -> 0 | Q40: =VLOOKUP(B40,'Analysis 1.3'!$AA$1:$AF$1454,5,FALSE) -> One time | R40: =VLOOKUP(B40,'Analysis 1.3'!$AA$1:$AF$1454,6,FALSE) -> Recent | S40: =VLOOKUP(B40,'Analysis 1.3'!$AA$1:$AF$1454,4,FALSE) -> 53.945139
A41: 1243085 | B41: 39 | C41: USA | D41: 45241.069 | E41: Whatsapp | F41: Frederique Citeaux | G41: 6819 | H41: =VLOOKUP(B41,'Customers (2)'!$A$1:$F$2501,2,0) -> USA | I41: =VLOOKUP(B41,'Customers (2)'!$A$1:$F$2501,3,0) -> F | J41: =VLOOKUP(B41,'Customers (2)'!$A$1:$F$2501,4,0) -> 46 | K41: =VLOOKUP(B41,'Customers (2)'!$A$1:$F$2501,5,0) -> A | L41: =VLOOKUP(B41,'Customers (2)'!$A$1:$F$2501,6,0) -> Middle | M41: =TEXT(D41,"MMMM") -> November | N41: =TEXT(D41,"dddd") -> Saturday | O41: =TEXT(D41,"HH:mm:ss") -> 01:39:00 | P41: =HOUR(D41) -> 1 | Q41: =VLOOKUP(B41,'Analysis 1.3'!$AA$1:$AF$1454,5,FALSE) -> One time | R41: =VLOOKUP(B41,'Analysis 1.3'!$AA$1:$AF$1454,6,FALSE) -> Recent | S41: =VLOOKUP(B41,'Analysis 1.3'!$AA$1:$AF$1454,4,FALSE) -> 50.913194 | W41: UL | X41: =X38+(1.5*X39) -> 15052.125 | AF41: UL | AG41: =AG37+(1.58*AG38) -> 127.88
A42: 245474 | B42: 40 | C42: Australia | D42: 45248.967 | E42: Other | F42: Arnold Cruz | G42: 3933 | H42: =VLOOKUP(B42,'Customers (2)'!$A$1:$F$2501,2,0) -> Australia | I42: =VLOOKUP(B42,'Customers (2)'!$A$1:$F$2501,3,0) -> F | J42: =VLOOKUP(B42,'Customers (2)'!$A$1:$F$2501,4,0) -> 37 | K42: =VLOOKUP(B42,'Customers (2)'!$A$1:$F$2501,5,0) -> A | L42: =VLOOKUP(B42,'Customers (2)'!$A$1:$F$2501,6,0) -> Middle | M42: =TEXT(D42,"MMMM") -> November | N42: =TEXT(D42,"dddd") -> Saturday | O42: =TEXT(D42,"HH:mm:ss") -> 23:13:00 | P42: =HOUR(D42) -> 23 | Q42: =VLOOKUP(B42,'Analysis 1.3'!$AA$1:$AF$1454,5,FALSE) -> Repeat | R42: =VLOOKUP(B42,'Analysis 1.3'!$AA$1:$AF$1454,6,FALSE) -> Recent | S42: =VLOOKUP(B42,'Analysis 1.3'!$AA$1:$AF$1454,4,FALSE) -> 43.014583 | W42: LL | X42: =X37-(1.5*X39) -> -5248.875 | AF42: LL | AG42: =AG36-(1.5*AG38) -> -19
A43: 588730 | B43: 40 | C43: Australia | D43: 45163.014 | E43: Other | F43: Paul Henriot | G43: 238 | H43: =VLOOKUP(B43,'Customers (2)'!$A$1:$F$2501,2,0) -> Australia | I43: =VLOOKUP(B43,'Customers (2)'!$A$1:$F$2501,3,0) -> F | J43: =VLOOKUP(B43,'Customers (2)'!$A$1:$F$2501,4,0) -> 37 | K43: =VLOOKUP(B43,'Customers (2)'!$A$1:$F$2501,5,0) -> A | L43: =VLOOKUP(B43,'Customers (2)'!$A$1:$F$2501,6,0) -> Middle | M43: =TEXT(D43,"MMMM") -> August | N43: =TEXT(D43,"dddd") -> Friday | O43: =TEXT(D43,"HH:mm:ss") -> 00:20:00 | P43: =HOUR(D43) -> 0 | Q43: =VLOOKUP(B43,'Analysis 1.3'!$AA$1:$AF$1454,5,FALSE) -> Repeat | R43: =VLOOKUP(B43,'Analysis 1.3'!$AA$1:$AF$1454,6,FALSE) -> Recent | S43: =VLOOKUP(B43,'Analysis 1.3'!$AA$1:$AF$1454,4,FALSE) -> 43.014583
A44: 926206 | B44: 41 | C44: Australia | D44: 44982.958 | E44: App | F44: Kalle Suominen | G44: 3952 | H44: =VLOOKUP(B44,'Customers (2)'!$A$1:$F$2501,2,0) -> Australia | I44: =VLOOKUP(B44,'Customers (2)'!$A$1:$F$2501,3,0) -> F | J44: =VLOOKUP(B44,'Customers (2)'!$A$1:$F$2501,4,0) -> 42 | K44: =VLOOKUP(B44,'Customers (2)'!$A$1:$F$2501,5,0) -> A | L44: =VLOOKUP(B44,'Customers (2)'!$A$1:$F$2501,6,0) -> Middle | M44: =TEXT(D44,"MMMM") -> February | N44: =TEXT(D44,"dddd") -> Saturday | O44: =TEXT(D44,"HH:mm:ss") -> 23:00:00 | P44: =HOUR(D44) -> 23 | Q44: =VLOOKUP(B44,'Analysis 1.3'!$AA$1:$AF$1454,5,FALSE) -> One time | R44: =VLOOKUP(B44,'Analysis 1.3'!$AA$1:$AF$1454,6,FALSE) -> Lost | S44: =VLOOKUP(B44,'Analysis 1.3'!$AA$1:$AF$1454,4,FALSE) -> 309.02361
A45: 310303 | B45: 42 | C45: Spain | D45: 45135.019 | E45: Other | F45: Adrian Huxley | G45: 369 | H45: =VLOOKUP(B45,'Customers (2)'!$A$1:$F$2501,2,0) -> Spain | I45: =VLOOKUP(B45,'Customers (2)'!$A$1:$F$2501,3,0) -> F | J45: =VLOOKUP(B45,'Customers (2)'!$A$1:$F$2501,4,0) -> 43 | K45: =VLOOKUP(B45,'Customers (2)'!$A$1:$F$2501,5,0) -> A | L45: =VLOOKUP(B45,'Customers (2)'!$A$1:$F$2501,6,0) -> Middle | M45: =TEXT(D45,"MMMM") -> July | N45: =TEXT(D45,"dddd") -> Friday | O45: =TEXT(D45,"HH:mm:ss") -> 00:28:00 | P45: =HOUR(D45) -> 0 | Q45: =VLOOKUP(B45,'Analysis 1.3'!$AA$1:$AF$1454,5,FALSE) -> Repeat | R45: =VLOOKUP(B45,'Analysis 1.3'!$AA$1:$AF$1454,6,FALSE) -> Passive | S45: =VLOOKUP(B45,'Analysis 1.3'!$AA$1:$AF$1454,4,FALSE) -> 156.9625
A46: 1641043 | B46: 42 | C46: Spain | D46: 44976.96 | E46: Other | F46: Kwai Yu | G46: 8182 | H46: =VLOOKUP(B46,'Customers (2)'!$A$1:$F$2501,2,0) -> Spain | I46: =VLOOKUP(B46,'Customers (2)'!$A$1:$F$2501,3,0) -> F | J46: =VLOOKUP(B46,'Customers (2)'!$A$1:$F$2501,4,0) -> 43 | K46: =VLOOKUP(B46,'Customers (2)'!$A$1:$F$2501,5,0) -> A | L46: =VLOOKUP(B46,'Customers (2)'!$A$1:$F$2501,6,0) -> Middle | M46: =TEXT(D46,"MMMM") -> February | N46: =TEXT(D46,"dddd") -> Sunday | O46: =TEXT(D46,"HH:mm:ss") -> 23:02:00 | P46: =HOUR(D46) -> 23 | Q46: =VLOOKUP(B46,'Analysis 1.3'!$AA$1:$AF$1454,5,FALSE) -> Repeat | R46: =VLOOKUP(B46,'Analysis 1.3'!$AA$1:$AF$1454,6,FALSE) -> Passive | S46: =VLOOKUP(B46,'Analysis 1.3'!$AA$1:$AF$1454,4,FALSE) -> 156.9625
...

Sheet Customers (2)
A1: Customer ID | B1: Customer Country | C1: Gender | D1: Age | E1: Category | F1: Age_group | G1: Average Age by country | J1: =AVERAGE(D2:D2501) -> 53.9684
A2: 1 | B2: France | C2: M | D2: 31 | E2: A | F2: =_xlfn.IFS(D2>=60, "Senior", D2<35, "Young", D2<60, "Middle") -> Young | G2: =VLOOKUP(B2,'Analysis 1.3'!$E$1:$F$15,2,FALSE) -> 54.003086 | M2: Age | N2: 18-90 | O2: 8 Missing Values
A3: 2 | B3: Spain | C3: M | D3: 49 | E3: A | F3: =_xlfn.IFS(D3>=60, "Senior", D3<35, "Young", D3<60, "Middle") -> Middle | G3: =VLOOKUP(B3,'Analysis 1.3'!$E$1:$F$15,2,FALSE) -> 48.434944 | H3: Catageory | M3: Countries | N3: 14
A4: 3 | B4: USA | C4: M | D4: 39 | E4: A | F4: =_xlfn.IFS(D4>=60, "Senior", D4<35, "Young", D4<60, "Middle") -> Middle | G4: =VLOOKUP(B4,'Analysis 1.3'!$E$1:$F$15,2,FALSE) -> 54.707207 | I4: A | J4: =COUNTIF($E$1:$E$2501,$I4) -> 500 | M4: Gender | N4: M & F
A5: 4 | B5: Australia | C5: M | D5: 54 | E5: A | F5: =_xlfn.IFS(D5>=60, "Senior", D5<35, "Young", D5<60, "Middle") -> Middle | G5: =VLOOKUP(B5,'Analysis 1.3'!$E$1:$F$15,2,FALSE) -> 52.833333 | I5: B | J5: =COUNTIF($E$1:$E$2501,$I5) -> 500 | M5: Category | N5: A,B,C,D,E
A6: 5 | B6: Denmark | C6: M | D6: 81 | E6: A | F6: =_xlfn.IFS(D6>=60, "Senior", D6<35, "Young", D6<60, "Middle") -> Senior | G6: =VLOOKUP(B6,'Analysis 1.3'!$E$1:$F$15,2,FALSE) -> 53.469697 | I6: C | J6: =COUNTIF($E$1:$E$2501,$I6) -> 500
A7: 6 | B7: USA | C7: F | D7: 62 | E7: A | F7: =_xlfn.IFS(D7>=60, "Senior", D7<35, "Young", D7<60, "Middle") -> Senior | G7: =VLOOKUP(B7,'Analysis 1.3'!$E$1:$F$15,2,FALSE) -> 54.707207 | I7: D | J7: =COUNTIF($E$1:$E$2501,$I7) -> 500
A8: 7 | B8: Singapore | C8: M | D8: 76 | E8: A | F8: =_xlfn.IFS(D8>=60, "Senior", D8<35, "Young", D8<60, "Middle") -> Senior | G8: =VLOOKUP(B8,'Analysis 1.3'!$E$1:$F$15,2,FALSE) -> 53.742268 | I8: E | J8: =COUNTIF($E$1:$E$2501,$I8) -> 500 | M8: young | N8: <30
A9: 8 | B9: France | C9: F | D9: 70 | E9: A | F9: =_xlfn.IFS(D9>=60, "Senior", D9<35, "Young", D9<60, "Middle") -> Senior | G9: =VLOOKUP(B9,'Analysis 1.3'!$E$1:$F$15,2,FALSE) -> 54.003086 | M9: middle | N9: <60
A10: 9 | B10: France | C10: F | D10: 75 | E10: A | F10: =_xlfn.IFS(D10>=60, "Senior", D10<35, "Young", D10<60, "Middle") -> Senior | G10: =VLOOKUP(B10,'Analysis 1.3'!$E$1:$F$15,2,FALSE) -> 54.003086 | H10: Gender | M10: Senior | N10: >=60
A11: 10 | B11: Norway | C11: F | D11: 32 | E11: A | F11: =_xlfn.IFS(D11>=60, "Senior", D11<35, "Young", D11<60, "Middle") -> Young | G11: =VLOOKUP(B11,'Analysis 1.3'!$E$1:$F$15,2,FALSE) -> 54.725 | I11: M | J11: =COUNTIF($C$1:$C$2501,$I11) -> 1243
A12: 11 | B12: USA | C12: F | D12: 82 | E12: A | F12: =_xlfn.IFS(D12>=60, "Senior", D12<35, "Young", D12<60, "Middle") -> Senior | G12: =VLOOKUP(B12,'Analysis 1.3'!$E$1:$F$15,2,FALSE) -> 54.707207 | I12: F | J12: =COUNTIF($C$1:$C$2501,$I12) -> 1257
A13: 12 | B13: Spain | C13: F | D13: 65 | E13: A | F13: =_xlfn.IFS(D13>=60, "Senior", D13<35, "Young", D13<60, "Middle") -> Senior | G13: =VLOOKUP(B13,'Analysis 1.3'!$E$1:$F$15,2,FALSE) -> 48.434944
A14: 13 | B14: Spain | C14: F | D14: 84 | E14: A | F14: =_xlfn.IFS(D14>=60, "Senior", D14<35, "Young", D14<60, "Middle") -> Senior | G14: =VLOOKUP(B14,'Analysis 1.3'!$E$1:$F$15,2,FALSE) -> 48.434944 | H14: Countrywise gender | I14: France | J14: =COUNTIF($B$1:$B$2501,$I14) -> 334
A15: 14 | B15: Australia | C15: M | D15: 64 | E15: A | F15: =_xlfn.IFS(D15>=60, "Senior", D15<35, "Young", D15<60, "Middle") -> Senior | G15: =VLOOKUP(B15,'Analysis 1.3'!$E$1:$F$15,2,FALSE) -> 52.833333 | I15: Spain | J15: =COUNTIF($B$1:$B$2501,$I15) -> 282
A16: 15 | B16: Germany | C16: F | D16: 48 | E16: A | F16: =_xlfn.IFS(D16>=60, "Senior", D16<35, "Young", D16<60, "Middle") -> Middle | G16: =VLOOKUP(B16,'Analysis 1.3'!$E$1:$F$15,2,FALSE) -> 49.655172 | I16: USA | J16: =COUNTIF($B$1:$B$2501,$I16) -> 907
A17: 16 | B17: Norway | C17: F | D17: 81 | E17: A | F17: =_xlfn.IFS(D17>=60, "Senior", D17<35, "Young", D17<60, "Middle") -> Senior | G17: =VLOOKUP(B17,'Analysis 1.3'!$E$1:$F$15,2,FALSE) -> 54.725 | I17: Australia | J17: =COUNTIF($B$1:$B$2501,$I17) -> 208
A18: 17 | B18: USA | C18: M | D18: 63 | E18: A | F18: =_xlfn.IFS(D18>=60, "Senior", D18<35, "Young", D18<60, "Middle") -> Senior | G18: =VLOOKUP(B18,'Analysis 1.3'!$E$1:$F$15,2,FALSE) -> 54.707207 | I18: Denmark | J18: =COUNTIF($B$1:$B$2501,$I18) -> 68
A19: 18 | B19: USA | C19: F | D19: 85 | E19: A | F19: =_xlfn.IFS(D19>=60, "Senior", D19<35, "Young", D19<60, "Middle") -> Senior | G19: =VLOOKUP(B19,'Analysis 1.3'!$E$1:$F$15,2,FALSE) -> 54.707207 | I19: Singapore | J19: =COUNTIF($B$1:$B$2501,$I19) -> 86
A20: 19 | B20: USA | C20: F | D20: 35 | E20: A | F20: =_xlfn.IFS(D20>=60, "Senior", D20<35, "Young", D20<60, "Middle") -> Middle | G20: =VLOOKUP(B20,'Analysis 1.3'!$E$1:$F$15,2,FALSE) -> 54.707207 | I20: Norway | J20: =COUNTIF($B$1:$B$2501,$I20) -> 37
A21: 20 | B21: USA | C21: F | D21: 38 | E21: A | F21: =_xlfn.IFS(D21>=60, "Senior", D21<35, "Young", D21<60, "Middle") -> Middle | G21: =VLOOKUP(B21,'Analysis 1.3'!$E$1:$F$15,2,FALSE) -> 54.707207 | I21: Germany | J21: =COUNTIF($B$1:$B$2501,$I21) -> 63
A22: 21 | B22: Spain | C22: F | D22: 68 | E22: A | F22: =_xlfn.IFS(D22>=60, "Senior", D22<35, "Young", D22<60, "Middle") -> Senior | G22: =VLOOKUP(B22,'Analysis 1.3'!$E$1:$F$15,2,FALSE) -> 48.434944 | I22: Austria | J22: =COUNTIF($B$1:$B$2501,$I22) -> 60
A23: 22 | B23: Spain | C23: F | D23: 78 | E23: A | F23: =_xlfn.IFS(D23>=60, "Senior", D23<35, "Young", D23<60, "Middle") -> Senior | G23: =VLOOKUP(B23,'Analysis 1.3'!$E$1:$F$15,2,FALSE) -> 48.434944 | I23: Finland | J23: =COUNTIF($B$1:$B$2501,$I23) -> 70
A24: 23 | B24: Spain | C24: F | D24: 62 | E24: A | F24: =_xlfn.IFS(D24>=60, "Senior", D24<35, "Young", D24<60, "Middle") -> Senior | G24: =VLOOKUP(B24,'Analysis 1.3'!$E$1:$F$15,2,FALSE) -> 48.434944 | I24: Italy | J24: =COUNTIF($B$1:$B$2501,$I24) -> 120
A25: 24 | B25: Spain | C25: F | D25: 47 | E25: A | F25: =_xlfn.IFS(D25>=60, "Senior", D25<35, "Young", D25<60, "Middle") -> Middle | G25: =VLOOKUP(B25,'Analysis 1.3'!$E$1:$F$15,2,FALSE) -> 48.434944 | I25: India | J25: =COUNTIF($B$1:$B$2501,$I25) -> 217
A26: 25 | B26: USA | C26: M | D26: 59 | E26: A | F26: =_xlfn.IFS(D26>=60, "Senior", D26<35, "Young", D26<60, "Middle") -> Middle | G26: =VLOOKUP(B26,'Analysis 1.3'!$E$1:$F$15,2,FALSE) -> 54.707207 | I26: Ireland | J26: =COUNTIF($B$1:$B$2501,$I26) -> 17
A27: 26 | B27: France | C27: M | D27: 27 | E27: A | F27: =_xlfn.IFS(D27>=60, "Senior", D27<35, "Young", D27<60, "Middle") -> Young | G27: =VLOOKUP(B27,'Analysis 1.3'!$E$1:$F$15,2,FALSE) -> 54.003086 | I27: Switzerland | J27: =COUNTIF($B$1:$B$2501,$I27) -> 31
A28: 27 | B28: USA | C28: F | D28: 66 | E28: A | F28: =_xlfn.IFS(D28>=60, "Senior", D28<35, "Young", D28<60, "Middle") -> Senior | G28: =VLOOKUP(B28,'Analysis 1.3'!$E$1:$F$15,2,FALSE) -> 54.707207
A29: 28 | B29: Singapore | C29: M | D29: 77 | E29: A | F29: =_xlfn.IFS(D29>=60, "Senior", D29<35, "Young", D29<60, "Middle") -> Senior | G29: =VLOOKUP(B29,'Analysis 1.3'!$E$1:$F$15,2,FALSE) -> 53.742268
A30: 29 | B30: Spain | C30: F | D30: 19 | E30: A | F30: =_xlfn.IFS(D30>=60, "Senior", D30<35, "Young", D30<60, "Middle") -> Young | G30: =VLOOKUP(B30,'Analysis 1.3'!$E$1:$F$15,2,FALSE) -> 48.434944 | J30: M | K30: F
A31: 30 | B31: France | C31: F | D31: 72 | E31: A | F31: =_xlfn.IFS(D31>=60, "Senior", D31<35, "Young", D31<60, "Middle") -> Senior | G31: =VLOOKUP(B31,'Analysis 1.3'!$E$1:$F$15,2,FALSE) -> 54.003086 | I31: France | J31: =COUNTIFS($B$1:$B$2501,$I31,$C$1:$C$2501,J$30) -> 181 | K31: =COUNTIFS($B$1:$B$2501,$I31,$C$1:$C$2501,K$30) -> 153
A32: 31 | B32: USA | C32: M | D32: 22 | E32: A | F32: =_xlfn.IFS(D32>=60, "Senior", D32<35, "Young", D32<60, "Middle") -> Young | G32: =VLOOKUP(B32,'Analysis 1.3'!$E$1:$F$15,2,FALSE) -> 54.707207 | I32: Spain | J32: =COUNTIFS($B$1:$B$2501,$I32,$C$1:$C$2501,J$30) -> 130 | K32: =COUNTIFS($B$1:$B$2501,$I32,$C$1:$C$2501,K$30) -> 152
A33: 32 | B33: Spain | C33: F | D33: 55 | E33: A | F33: =_xlfn.IFS(D33>=60, "Senior", D33<35, "Young", D33<60, "Middle") -> Middle | G33: =VLOOKUP(B33,'Analysis 1.3'!$E$1:$F$15,2,FALSE) -> 48.434944 | I33: USA | J33: =COUNTIFS($B$1:$B$2501,$I33,$C$1:$C$2501,J$30) -> 454 | K33: =COUNTIFS($B$1:$B$2501,$I33,$C$1:$C$2501,K$30) -> 453
A34: 33 | B34: Spain | C34: M | D34: 53 | E34: A | F34: =_xlfn.IFS(D34>=60, "Senior", D34<35, "Young", D34<60, "Middle") -> Middle | G34: =VLOOKUP(B34,'Analysis 1.3'!$E$1:$F$15,2,FALSE) -> 48.434944 | I34: Australia | J34: =COUNTIFS($B$1:$B$2501,$I34,$C$1:$C$2501,J$30) -> 102 | K34: =COUNTIFS($B$1:$B$2501,$I34,$C$1:$C$2501,K$30) -> 106
A35: 34 | B35: Australia | C35: F | D35: 20 | E35: A | F35: =_xlfn.IFS(D35>=60, "Senior", D35<35, "Young", D35<60, "Middle") -> Young | G35: =VLOOKUP(B35,'Analysis 1.3'!$E$1:$F$15,2,FALSE) -> 52.833333 | I35: Denmark | J35: =COUNTIFS($B$1:$B$2501,$I35,$C$1:$C$2501,J$30) -> 33 | K35: =COUNTIFS($B$1:$B$2501,$I35,$C$1:$C$2501,K$30) -> 35
A36: 35 | B36: Australia | C36: M | D36: 19 | E36: A | F36: =_xlfn.IFS(D36>=60, "Senior", D36<35, "Young", D36<60, "Middle") -> Young | G36: =VLOOKUP(B36,'Analysis 1.3'!$E$1:$F$15,2,FALSE) -> 52.833333 | I36: Singapore | J36: =COUNTIFS($B$1:$B$2501,$I36,$C$1:$C$2501,J$30) -> 44 | K36: =COUNTIFS($B$1:$B$2501,$I36,$C$1:$C$2501,K$30) -> 42
A37: 36 | B37: USA | C37: M | D37: 63 | E37: A | F37: =_xlfn.IFS(D37>=60, "Senior", D37<35, "Young", D37<60, "Middle") -> Senior | G37: =VLOOKUP(B37,'Analysis 1.3'!$E$1:$F$15,2,FALSE) -> 54.707207 | I37: Norway | J37: =COUNTIFS($B$1:$B$2501,$I37,$C$1:$C$2501,J$30) -> 16 | K37: =COUNTIFS($B$1:$B$2501,$I37,$C$1:$C$2501,K$30) -> 21
A38: 37 | B38: Spain | C38: M | D38: 35 | E38: A | F38: =_xlfn.IFS(D38>=60, "Senior", D38<35, "Young", D38<60, "Middle") -> Middle | G38: =VLOOKUP(B38,'Analysis 1.3'!$E$1:$F$15,2,FALSE) -> 48.434944 | I38: Germany | J38: =COUNTIFS($B$1:$B$2501,$I38,$C$1:$C$2501,J$30) -> 31 | K38: =COUNTIFS($B$1:$B$2501,$I38,$C$1:$C$2501,K$30) -> 32
A39: 38 | B39: Austria | C39: M | D39: 53 | E39: A | F39: =_xlfn.IFS(D39>=60, "Senior", D39<35, "Young", D39<60, "Middle") -> Middle | G39: =VLOOKUP(B39,'Analysis 1.3'!$E$1:$F$15,2,FALSE) -> 47.44186 | I39: Austria | J39: =COUNTIFS($B$1:$B$2501,$I39,$C$1:$C$2501,J$30) -> 35 | K39: =COUNTIFS($B$1:$B$2501,$I39,$C$1:$C$2501,K$30) -> 25
A40: 39 | B40: USA | C40: F | D40: 46 | E40: A | F40: =_xlfn.IFS(D40>=60, "Senior", D40<35, "Young", D40<60, "Middle") -> Middle | G40: =VLOOKUP(B40,'Analysis 1.3'!$E$1:$F$15,2,FALSE) -> 54.707207 | I40: Finland | J40: =COUNTIFS($B$1:$B$2501,$I40,$C$1:$C$2501,J$30) -> 36 | K40: =COUNTIFS($B$1:$B$2501,$I40,$C$1:$C$2501,K$30) -> 34
...

Sheet Customers
A1: Customer ID | B1: Customer Country | C1: Gender | D1: Age | E1: Category
A2: 1 | B2: France | C2: M | D2: 31 | E2: A
A3: 2 | B3: Spain | C3: M | D3: 49 | E3: A
A4: 3 | B4: USA | C4: M | D4: 39 | E4: A
A5: 4 | B5: Australia | C5: M | E5: A
A6: 5 | B6: Denmark | C6: M | D6: 81 | E6: A
A7: 6 | B7: USA | C7: F | D7: 62 | E7: A
A8: 7 | B8: Singapore | C8: M | D8: 76 | E8: A
A9: 8 | B9: France | C9: F | D9: 70 | E9: A
A10: 9 | B10: France | C10: F | D10: 75 | E10: A
A11: 10 | B11: Norway | C11: F | D11: 32 | E11: A
A12: 11 | B12: USA | C12: F | D12: 82 | E12: A
A13: 12 | B13: Spain | C13: F | D13: 65 | E13: A
A14: 13 | B14: Spain | C14: F | D14: 84 | E14: A
A15: 14 | B15: Australia | C15: M | D15: 64 | E15: A
A16: 15 | B16: Germany | C16: F | D16: 48 | E16: A
A17: 16 | B17: Norway | C17: F | D17: 81 | E17: A
... A1260: 1259 | B1260: USA | C1260: M | D1260: 45 | E1260: C
A1261: 1260 | B1261: France | C1261: M | E1261: C
A1262: 1261 | B1262: USA | C1262: M | D1262: 49 | E1262: C
A1263: 1262 | B1263: USA | C1263: M | D1263: 41 | E1263: C
A1264: 1263 | B1264: USA | C1264: F | D1264: 78 | E1264: C
A1265: 1264 | B1265: Italy | C1265: F | D1265: 47 | E1265: C
A1266: 1265 | B1266: USA | C1266: M | D1266: 72 | E1266: C
A1267: 1266 | B1267: USA | C1267: M | D1267: 42 | E1267: C
A1268: 1267 | B1268: Italy | C1268: M | D1268: 62 | E1268: C
A1269: 1268 | B1269: USA | C1269: M | D1269: 48 | E1269: C
A1270: 1269 | B1270: Switzerland | C1270: M | D1270: 48 | E1270: C
A1271: 1270 | B1271: USA | C1271: M | D1271: 48 | E1271: C
A1272: 1271 | B1272: France | C1272: F | D1272: 43 | E1272: C
A1273: 1272 | B1273: Australia | C1273: F | D1273: 39 | E1273: C
... A1497: 1496 | B1497: USA | C1497: F | D1497: 74 | E1497: C
A1498: 1497 | B1498: Spain | C1498: F | E1498: C
A1499: 1498 | B1499: Germany | C1499: F | D1499: 75 | E1499: C
A1500: 1499 | B1500: USA | C1500: F | D1500: 48 | E1500: C
A1501: 1500 | B1501: USA | C1501: M | D1501: 19 | E1501: C
A1502: 1501 | B1502: USA | C1502: M | D1502: 51 | E1502: D
A1503: 1502 | B1503: Spain | C1503: F | D1503: 33 | E1503: D
A1504: 1503 | B1504: Norway | C1504: F | D1504: 79 | E1504: D
A1505: 1504 | B1505: France | C1505: F | D1505: 33 | E1505: D
...

Sheet Sales Targets (2)
A1: Sales POC | B1: Sales Manager First Name | C1: Sales Manager Last Name | D1: Sales Team | E1: 2023 Sales Target | H1: 2023 Sales Target | I1: count | J1: Average sales
A2: Kalle Suominen | B2: Amelia | C2: Johnson | D2: Epsilon | E2: 100000 | H2: 100000 | I2: =COUNTIF($E$1:$E$93,$H2) -> 36 | J2: =AVERAGE(E1:E93) -> 139239.13
A3: Julie Brown | B3: Lukas | C3: Schmidt | D3: Alpha | E3: 200000 | H3: 200000 | I3: =COUNTIF($E$1:$E$93,$H3) -> 10
A4: Jeff Young | B4: Olivia | C4: Jensen | D4: Beta | E4: 200000 | H4: 250000 | I4: =COUNTIF($E$1:$E$93,$H4) -> 3
A5: Kyung Yu | B5: Sofia | C5: Laine | D5: Gamma | E5: 100000 | H5: 1000000 | I5: =COUNTIF($E$1:$E$93,$H5) -> 2
A6: Adrian Huxley | B6: Chloe | C6: Dupont | D6: Beta | E6: 200000 | H6: 50000 | I6: =COUNTIF($E$1:$E$93,$H6) -> 6
A7: Kwai Yu | B7: Alexander | C7: Müller | D7: Alpha | E7: 200000 | H7: 150000 | I7: =COUNTIF($E$1:$E$93,$H7) -> 23
A8: Jytte Petersen | B8: Liam | C8: O'Sullivan | D8: Beta | E8: 100000 | H8: 80000 | I8: =COUNTIF($E$1:$E$93,$H8) -> 7
A9: Paul Henriot | B9: Sophia | C9: Rossi | D9: Beta | E9: 200000 | H9: 30000 | I9: =COUNTIF($E$1:$E$93,$H9) -> 5
A10: Sue King | B10: Emma | C10: Hansen | D10: Gamma | E10: 100000
A11: Victoria Ashworth | B11: Ethan | C11: Lee | D11: Beta | E11: 250000 | H11: Sales Team | I11: count | J11: Average sales
A12: Anna O'Hara | B12: Isabella | C12: Garcia | D12: Alpha | E12: 200000 | H12: Epsilon | I12: =COUNTIF($D$1:$D$93,$H12) -> 13 | J12: =AVERAGEIF($D$1:$D$93,$H12,$E$1:$E$93) -> 113846.15 | K12: =J12/$J$2 -> 0.81763046
A13: Diego Freyre | B13: Noah | C13: Meier | D13: Alpha | E13: 1000000 | H13: Alpha | I13: =COUNTIF($D$1:$D$93,$H13) -> 22 | J13: =AVERAGEIF($D$1:$D$93,$H13,$E$1:$E$93) -> 167727.27 | K13: =J13/$J$2 -> 1.2045987
A14: Akiko Shimamura | B14: Ava | C14: Williams | D14: Epsilon | E14: 100000 | H14: Beta | I14: =COUNTIF($D$1:$D$93,$H14) -> 24 | J14: =AVERAGEIF($D$1:$D$93,$H14,$E$1:$E$93) -> 121666.67 | K14: =J14/$J$2 -> 0.87379651
A15: Janine Labrune | B15: Dev | C15: Patel | D15: Delta | E15: 200000 | H15: Gamma | I15: =COUNTIF($D$1:$D$93,$H15) -> 21 | J15: =AVERAGEIF($D$1:$D$93,$H15,$E$1:$E$93) -> 114761.9 | K15: =J15/$J$2 -> 0.82420728
A16: Thomas Hardy | B16: Mia | C16: Khan | D16: Epsilon | E16: 50000 | H16: Delta | I16: =COUNTIF($D$1:$D$93,$H16) -> 12 | J16: =AVERAGEIF($D$1:$D$93,$H16,$E$1:$E$93) -> 192500 | K16: =J16/$J$2 -> 1.3825137
A17: Annette Roulet | B17: William | C17: Brown | D17: Gamma | E17: 100000
A18: Steve Frick | B18: Sophie | C18: Gruber | D18: Delta | E18: 100000
A19: Mary Saveley | B19: Lucas | C19: Nielsen | D19: Gamma | E19: 150000
A20: Henriette Pfalzheim | B20: Aino | C20: Virtanen | D20: Beta | E20: 150000
A21: Laurence Lebihan | B21: Emily | C21: Dubois | D21: Delta | E21: 150000
A22: Catherine Dewey | B22: Benjamin | C22: Weber | D22: Epsilon | E22: 100000
A23: Giovanni Rovelli | B23: Emily | C23: Murphy | D23: Alpha | E23: 150000
A24: Paolo Accorti | B24: Marco | C24: Bianchi | D24: Alpha | E24: 150000
A25: Daniel Da Cunha | B25: Lucas | C25: Olsen | D25: Gamma | E25: 100000
A26: Valarie Nelson | B26: Benjamin | C26: Chen | D26: Delta | E26: 1000000
A27: Frederique Citeaux | B27: Daniela | C27: Hernandez | D27: Gamma | E27: 100000
A28: Arnold Cruz | B28: Liam | C28: Baumann | D28: Beta | E28: 100000
... A93: Jesus Fernandez | B93: Ava | C93: Williams | D93: Epsilon | E93: 50000

Sheet Brain Stroming 
A1: Imagine you have to present a PPT to the CEO
A2: Define the North start Metric
A3: Increase the repeat order rate
B4: 1 | C4: Demographic of the customers
B5: 2 | C5: Time of the customer
B6: 3 | C6: sources
B7: 4 | C7: Chrun ratio
B8: 5 | C8: Sales team performance
B9: 6 | C9: Price sensitivity
B11: 1 | C11: Demographic of the customers
C12: Customer Count | D12: Gender | E12: Age | F12: Category | G12: vs | H12: Order value | I12: Order source | J12: Customer Id
B14: 2 | C14: Time of the customer
C15: Order datetime | E15: vs | F15: Order value | G15: order source | H15: order country | I15: category | J15: Age
B17: 3 | C17: sources
C18: Order Soure | E18: vs | F18: Customer Order value
B20: 4 | C20: Chrun ratio
C21: Customer ID | D21: vs | E21: Order Date time
C22: Customer ID | D22: vs | E22: Order Date time | F22: Country
B24: 5 | C24: Sales team performance
C25: Sales POC | D25: 2023 Sales Target
C26: Sales Team
B28: 6 | C28: Price sensitivity
C29: Order value | D29: vs Customer | E29: gender | F29: age | G29: Category
A33: Make pivots of count for column we discussed
A36: Do the same analysis for
A37: source | B37: 3rd analysis
A39: Question 2,3-a,b,c
A40: find outliers in order value

Sheet Analysis No.1
A1: Row Labels | B1: Count of Customer ID | C1: Sum of Customer ID | E1: Row Labels | F1: Count of Customer ID | H1: Average of Age | I1: Column Labels | L1: Row Labels | M1: Sum of Order Value | N1: Average of Order Value2 | O1: Count of Order ID | P1: Sum of Customer ID
A2: USA | B2: 907 | C2: 0.38573627 | E2: 18-27 | F2: 327 | H2: Row Labels | I2: F | J2: M | L2: Australia | M2: 0.079360193 | N2: 4920.2879 | O2: 198 | P2: 213333
A3: France | B3: 334 | C3: 0.13664742 | E3: 28-37 | F3: 360 | H3: Australia | I3: 51.943396 | J3: 55.431373 | L3: Austria | M3: 0.018240307 | N3: 5207.3488 | O3: 43 | P3: 57992
A4: Spain | B4: 282 | C4: 0.12947301 | E4: 38-47 | F4: 340 | H4: Austria | I4: 46.4 | J4: 55.971429 | L4: Denmark | M4: 0.02502955 | N4: 4655.4545 | O4: 66 | P4: 57203
A5: Australia | B5: 208 | C5: 0.083380088 | E5: 48-57 | F5: 324 | H5: Denmark | I5: 56.457143 | J5: 52.666667 | L5: Finland | M5: 0.026419184 | N5: 4913.9242 | O5: 66 | P5: 66698
A6: Italy | B6: 120 | C6: 0.048871331 | E6: 58-67 | F6: 372 | H6: Finland | I6: 62.558824 | J6: 54.777778 | L6: France | M6: 0.13362298 | N6: 5062.7809 | O6: 324 | P6: 323129
A7: India | B7: 217 | C7: 0.043507397 | E7: 68-77 | F7: 341 | H7: France | I7: 55.444444 | J7: 54.077348 | L7: Germany | M7: 0.024410124 | N7: 5166.4828 | O7: 58 | P7: 55296
A8: Singapore | B8: 86 | C8: 0.035051259 | E8: 78-87 | F8: 337 | H8: Germany | I8: 45.65625 | J8: 55.16129 | L8: India | M8: 0.11123006 | N8: 4842.0142 | O8: 282 | P8: 174809
A9: Austria | B9: 60 | C9: 0.02737593 | E9: 88-97 | F9: 99 | H9: India | I9: 53.982301 | J9: 55.365385 | L9: Ireland | M9: 0.0074915953 | N9: 4598.3 | O9: 20 | P9: 24260
A10: Denmark | B10: 68 | C10: 0.025710996 | E10: Grand Total | F10: 2500 | H10: Ireland | I10: 49.555556 | J10: 69.75 | L10: Italy | M10: 0.043969439 | N10: 4776.6726 | O10: 113 | P10: 111859
A11: Finland | B11: 70 | C11: 0.025644462 | H11: Italy | I11: 50.380952 | J11: 50.912281 | L11: Norway | M11: 0.01590345 | N11: 4880.725 | O11: 40 | P11: 30980
A12: Germany | B12: 63 | C12: 0.025066453 | H12: Norway | I12: 56.952381 | J12: 46.875 | L12: Singapore | M12: 0.039641362 | N12: 5016.8351 | O12: 97 | P12: 103138
A13: Switzerland | B13: 31 | C13: 0.014779368 | H13: Singapore | I13: 60.714286 | J13: 53.931818 | L13: Spain | M13: 0.11296932 | N13: 5155.3866 | O13: 269 | P13: 325127
A14: Norway | B14: 37 | C14: 0.012564574 | H14: Spain | I14: 50.480263 | J14: 52.615385 | L14: Switzerland | M14: 0.013514621 | N14: 4608.4444 | O14: 36 | P14: 46332
A15: Ireland | B15: 17 | C15: 0.0061914434 | H15: Switzerland | I15: 56.473684 | J15: 46.166667 | L15: USA | M15: 0.34819781 | N15: 4813.5563 | O15: 888 | P15: 922337
A16: Grand Total | B16: 2500 | C16: 1 | H16: USA | I16: 54.671082 | J16: 54.348018 | L16: Grand Total | M16: 1 | N16: 4910.356 | O16: 2500 | P16: 2512493
H17: Grand Total | I17: 53.851233 | J17: 54.086887
A19: Row Labels | B19: Count of Gender | C19: Count of Gender2 | H19: Count of Gender | I19: Column Labels
A20: F | B20: 1257 | C20: 0.5028 | H20: Row Labels | I20: F | J20: M | L20: Austria has very high average order value
A21: M | B21: 1243 | C21: 0.4972 | H21: Middle | I21: 409 | J21: 440 | L21: Top countries by avg order value Austria , France , Germany , Singapore , spain
A22: Grand Total | B22: 2500 | C22: 1 | H22: Senior | I22: 531 | J22: 534
H23: Young | I23: 317 | J23: 269 | L23: Most customers are from Usa
A24: Row Labels | B24: Count of Category | C24: Count of Category2 | H24: Grand Total | I24: 1257 | J24: 1243 | L24: 34.82 % of customers are coming from USA
A25: A | B25: 500 | C25: 0.2
A26: B | B26: 500 | C26: 0.2 | L26: Row Labels | M26: Sum of Order Value | N26: Average of Order Value | O26: Count of Order ID | P26: Distinct Count of Customer ID | Q26: Repeat Rate
